<?xml version="1.0"?>
<robot name="mob_rob">

    <!-- BASE LINK -->
    <link name="base_link">
        <visual>
            <geometry>
                <box size="0.4 0.3 0.3"/>
            </geometry>
            <material name="red">
                <color rgba="1 0 0 1"/>
            </material>
        </visual>
        <collision>
            <geometry>
                <box size="0.4 0.3 0.3"/>
            </geometry>
        </collision>
        <inertial>
            <mass value="1.0"/>
            <inertia ixx="0.015" iyy="0.0208" izz="0.0208" ixy="0" ixz="0" iyz="0"/>
        </inertial>
    </link>

    <!-- WHEELS -->
    <link name="front_left_wheel"> 
        <visual>
            <geometry>
                <cylinder length="0.05" radius="0.1"/>
            </geometry>
            <material name="black">
                <color rgba="0 0 0 1"/>
            </material>
        </visual>
        <collision>
            <geometry>
                <cylinder length="0.05" radius="0.1"/>
            </geometry>
        </collision>
        <inertial>
            <mass value="0.1"/>
            <inertia ixx="0.00027" iyy="0.00027" izz="0.0005" ixy="0" ixz="0" iyz="0"/>
        </inertial>
    </link>

    <link name="front_right_wheel"> 
        <visual>
            <geometry>
                <cylinder length="0.05" radius="0.1"/>
            </geometry>
            <material name="black">
                <color rgba="0 0 0 1"/>
            </material>
        </visual>
        <collision>
            <geometry>
                <cylinder length="0.05" radius="0.1"/>
            </geometry>
        </collision>
        <inertial>
            <mass value="0.1"/>
            <inertia ixx="0.00027" iyy="0.00027" izz="0.0005" ixy="0" ixz="0" iyz="0"/>
        </inertial>
    </link>

    <link name="back_left_wheel"> 
        <visual>
            <geometry>
                <cylinder length="0.05" radius="0.1"/>
            </geometry>
            <material name="black">
                <color rgba="0 0 0 1"/>
            </material>
        </visual>
        <collision>
            <geometry>
                <cylinder length="0.05" radius="0.1"/>
            </geometry>
        </collision>
        <inertial>
            <mass value="0.1"/>
            <inertia ixx="0.00027" iyy="0.00027" izz="0.0005" ixy="0" ixz="0" iyz="0"/>
        </inertial>
    </link>

    <link name="back_right_wheel"> 
        <visual>
            <geometry>
                <cylinder length="0.05" radius="0.1"/>
            </geometry>
            <material name="black">
                <color rgba="0 0 0 1"/>
            </material>
        </visual>
        <collision>
            <geometry>
                <cylinder length="0.05" radius="0.1"/>
            </geometry>
        </collision>
        <inertial>
            <mass value="0.1"/>
            <inertia ixx="0.00027" iyy="0.00027" izz="0.0005" ixy="0" ixz="0" iyz="0"/>
        </inertial>
    </link>

    <!-- WHEEL JOINTS -->
    <joint name="front_left_wheel_joint" type="continuous">
        <axis xyz="0 0 1"/>
        <parent link="base_link"/>
        <child link="front_left_wheel"/>
        <origin rpy="-1.5708 0 0" xyz="0.1125 0.175 -0.085"/>
    </joint>

    <joint name="front_right_wheel_joint" type="continuous">
        <axis xyz="0 0 1"/>
        <parent link="base_link"/>
        <child link="front_right_wheel"/>
        <origin rpy="-1.5708 0 0" xyz="0.1125 -0.175 -0.085"/>
    </joint>

    <joint name="back_left_wheel_joint" type="continuous">
        <axis xyz="0 0 1"/>
        <parent link="base_link"/>
        <child link="back_left_wheel"/>
        <origin rpy="-1.5708 0 0" xyz="-0.1125 0.175 -0.085"/>
    </joint>

    <joint name="back_right_wheel_joint" type="continuous">
        <axis xyz="0 0 1"/>
        <parent link="base_link"/>
        <child link="back_right_wheel"/>
        <origin rpy="-1.5708 0 0" xyz="-0.1125 -0.175 -0.085"/>
    </joint>

    <!-- SENSORS -->
    <link name="kinect_link">
        <visual>
            <geometry>
                <box size="0.038 0.038 0.038"/>
            </geometry>
            <material name="black"/>
        </visual>
        <collision>
            <geometry>
                <box size="0.038 0.038 0.038"/>
            </geometry>
        </collision>
        <inertial>
            <mass value="1e-5"/>
            <inertia ixx="6.65e-8" iyy="4.56e-9" izz="6.86e-8" ixy="0" ixz="0" iyz="0"/>
        </inertial>
    </link>

    <joint name="kinect_joint" type="fixed">
        <parent link="base_link"/>
        <child link="kinect_link"/>
        <origin rpy="0 0 0" xyz="0.2185 0 0.132"/>
    </joint>

    <link name="lidar_link">
        <visual>
            <geometry>
                <box size="0.038 0.038 0.038"/>
            </geometry>
            <material name="black"/>
        </visual>
        <collision>
            <geometry>
                <box size="0.038 0.038 0.038"/>
            </geometry>
        </collision>
        <inertial>
            <mass value="1e-5"/>
            <inertia ixx="6.65e-8" iyy="4.56e-9" izz="6.86e-8" ixy="0" ixz="0" iyz="0"/>
        </inertial>
    </link>

    <joint name="lidar_joint" type="fixed">
        <parent link="base_link"/>
        <child link="lidar_link"/>
        <origin rpy="0 0 0" xyz="0 0 0.1685"/>
    </joint>

    <!-- BASE FOOTPRINT -->
    <link name="base_footprint"/>
    <joint name="base_footprint_joint" type="fixed">
        <parent link="base_footprint"/>
        <child link="base_link"/>
        <origin rpy="0 0 0" xyz="0 0 0.185"/>
    </joint>

    <!-- GAZEBO MATERIALS -->
    <gazebo reference="base_link">
        <material>Gazebo/Red</material>
    </gazebo>
    <gazebo reference="front_left_wheel">
        <material>Gazebo/Black</material>
    </gazebo>
    <gazebo reference="back_left_wheel">
        <material>Gazebo/Black</material>
    </gazebo>
    <gazebo reference="front_right_wheel">
        <material>Gazebo/Black</material>
    </gazebo>
    <gazebo reference="back_right_wheel">
        <material>Gazebo/Black</material>
    </gazebo>
    <gazebo reference="kinect_link">
        <material>Gazebo/Black</material>
    </gazebo>

    <!-- GAZEBO PLUGINS -->
    <gazebo>
        <plugin name="gz::sim::systems::DiffDrive" filename="gz-sim-diff-drive-system">
            <odom_publish_frequency>30</odom_publish_frequency>
            <left_joint>front_left_wheel_joint</left_joint>
            <left_joint>back_left_wheel_joint</left_joint>
            <right_joint>front_right_wheel_joint</right_joint>
            <right_joint>back_right_wheel_joint</right_joint>
            <num_wheel_pairs>2</num_wheel_pairs>
            <wheel_separation>0.32</wheel_separation>
            <wheel_radius>0.1</wheel_radius>
            <max_wheel_torque>20</max_wheel_torque>
            <max_wheel_acceleration>1.0</max_wheel_acceleration>
            <odom_topic>odom</odom_topic>
            <frame_id>odom</frame_id>
            <child_frame_id>base_link</child_frame_id>
            <topic>cmd_vel</topic>
            <tf_topic>tf</tf_topic>
        </plugin>
    </gazebo>

    <gazebo>
        <plugin name="gz::sim::systems::JointStatePublisher" filename="gz-sim-joint-state-publisher-system">
            <topic>joint_state</topic>
            <joint_name>front_right_wheel_joint</joint_name>
            <joint_name>back_right_wheel_joint</joint_name>
            <joint_name>front_left_wheel_joint</joint_name>
            <joint_name>back_left_wheel_joint</joint_name>
        </plugin>
    </gazebo>

    <gazebo>
        <plugin name="gz::sim::systems::OdometryPublisher" filename = "gz-sim-odometry-publisher-system">
            <odom_frame>odom_fake</odom_frame>
            <robot_base_frame>base_link</robot_base_frame>
            <odom_topic>odom_fake</odom_topic>
            <tf_topic>tf</tf_topic>
        </plugin>
    </gazebo>

</robot>
