<?xml version="1.0"?>
<robot name="mob_rob">

  <material name="red">
    <color rgba="1 0 0 1"/>
  </material>
  <material name="black">
    <color rgba="0 0 0 1"/>
  </material>

  <link name="base_link">
    <visual>
      <geometry>
        <box size="0.4 0.3 0.3"/>
      </geometry>
      <material name="red"/>
    </visual>
    <collision>
      <geometry>
        <box size="0.4 0.3 0.3"/>
      </geometry>
    </collision>
    <inertial>
      <mass value="1.0"/>
      <inertia ixx="0.015" iyy="0.0208" izz="0.0208" ixy="0" ixz="0" iyz="0"/>
    </inertial>
  </link>

  <link name="front_left_wheel">
    <visual><geometry><cylinder length="0.05" radius="0.1"/></geometry><material name="black"/></visual>
    <collision><geometry><cylinder length="0.05" radius="0.1"/></geometry></collision>
    <inertial><mass value="0.1"/><inertia ixx="0.00027" iyy="0.00027" izz="0.0005" ixy="0" ixz="0" iyz="0"/></inertial>
  </link>
  <link name="front_right_wheel">
    <visual><geometry><cylinder length="0.05" radius="0.1"/></geometry><material name="black"/></visual>
    <collision><geometry><cylinder length="0.05" radius="0.1"/></geometry></collision>
    <inertial><mass value="0.1"/><inertia ixx="0.00027" iyy="0.00027" izz="0.0005" ixy="0" ixz="0" iyz="0"/></inertial>
  </link>
  <link name="back_left_wheel">
    <visual><geometry><cylinder length="0.05" radius="0.1"/></geometry><material name="black"/></visual>
    <collision><geometry><cylinder length="0.05" radius="0.1"/></geometry></collision>
    <inertial><mass value="0.1"/><inertia ixx="0.00027" iyy="0.00027" izz="0.0005" ixy="0" ixz="0" iyz="0"/></inertial>
  </link>
  <link name="back_right_wheel">
    <visual><geometry><cylinder length="0.05" radius="0.1"/></geometry><material name="black"/></visual>
    <collision><geometry><cylinder length="0.05" radius="0.1"/></geometry></collision>
    <inertial><mass value="0.1"/><inertia ixx="0.00027" iyy="0.00027" izz="0.0005" ixy="0" ixz="0" iyz="0"/></inertial>
  </link>

  <joint name="front_left_wheel_joint" type="continuous">
    <parent link="base_link"/><child link="front_left_wheel"/>
    <origin xyz="0.1125 0.175 -0.085" rpy="-1.5708 0 0"/><axis xyz="0 0 1"/>
  </joint>
  <joint name="front_right_wheel_joint" type="continuous">
    <parent link="base_link"/><child link="front_right_wheel"/>
    <origin xyz="0.1125 -0.175 -0.085" rpy="-1.5708 0 0"/><axis xyz="0 0 1"/>
  </joint>
  <joint name="back_left_wheel_joint" type="continuous">
    <parent link="base_link"/><child link="back_left_wheel"/>
    <origin xyz="-0.1125 0.175 -0.085" rpy="-1.5708 0 0"/><axis xyz="0 0 1"/>
  </joint>
  <joint name="back_right_wheel_joint" type="continuous">
    <parent link="base_link"/><child link="back_right_wheel"/>
    <origin xyz="-0.1125 -0.175 -0.085" rpy="-1.5708 0 0"/><axis xyz="0 0 1"/>
  </joint>

  <link name="base_footprint"/>
  <joint name="base_footprint_joint" type="fixed">
    <parent link="base_footprint"/><child link="base_link"/>
    <origin xyz="0 0 0.185" rpy="0 0 0"/>
  </joint>

  <link name="kinect_link">
    <visual><geometry><box size="0.038 0.038 0.038"/></geometry><material name="black"/></visual>
    <collision><geometry><box size="0.038 0.038 0.038"/></geometry></collision>
    <inertial><mass value="1e-5"/><inertia ixx="6.65e-8" iyy="4.56e-9" izz="6.86e-8" ixy="0" ixz="0" iyz="0"/></inertial>
  </link>
  <joint name="kinect_joint" type="fixed">
    <parent link="base_link"/><child link="kinect_link"/>
    <origin rpy="0 0 0" xyz="0.2185 0 0.132"/>
  </joint>

  <link name="lidar_link">
    <visual><geometry><box size="0.038 0.038 0.038"/></geometry><material name="black"/></visual>
    <collision><geometry><box size="0.038 0.038 0.038"/></geometry></collision>
    <inertial><mass value="1e-5"/><inertia ixx="6.65e-8" iyy="4.56e-9" izz="6.86e-8" ixy="0" ixz="0" iyz="0"/></inertial>
  </link>
  <joint name="lidar_joint" type="fixed">
    <parent link="base_link"/><child link="lidar_link"/>
    <origin rpy="0 0 0" xyz="0 0 0.1685"/>
  </joint>

  <gazebo>
    <plugin filename="gz-sim-diff-drive-system" name="gz::sim::systems::DiffDrive">
      <left_joint>front_left_wheel_joint</left_joint>
      <right_joint>front_right_wheel_joint</right_joint>
      <wheel_separation>0.35</wheel_separation>
      <wheel_radius>0.1</wheel_radius>
      <topic>cmd_vel</topic>
      <odom_topic>odom_fake</odom_topic>
      <frame_id>odom_fake</frame_id>
      <child_frame_id>base_link</child_frame_id>
    </plugin>
  </gazebo>

  <gazebo reference="lidar_link">
    <sensor type="gpu_lidar" name="lidar">
        <pose>0 0 0 0 0 0</pose>
        <update_rate>10</update_rate>
        <lidar>
        <scan>
            <horizontal>
            <samples>360</samples>
            <resolution>1</resolution>
            <min_angle>-1.5708</min_angle>
            <max_angle>1.5708</max_angle>
            </horizontal>
        </scan>
        <range>
            <min>0.15</min> 
            <max>10.0</max>
        </range>
        </lidar>
        <visualize>true</visualize>
        <topic>scan</topic>
        <gz_frame_id>lidar_link</gz_frame_id> </sensor>
    </gazebo>

  <gazebo reference="base_link"><material>Gazebo/Red</material></gazebo>
  <gazebo reference="front_left_wheel"><material>Gazebo/Black</material></gazebo>
  <gazebo reference="front_right_wheel"><material>Gazebo/Black</material></gazebo>
  <gazebo reference="back_left_wheel"><material>Gazebo/Black</material></gazebo>
  <gazebo reference="back_right_wheel"><material>Gazebo/Black</material></gazebo>

</robot>